<?xml version='1.0'?>
<sdf version='1.7'>
  <model name="rover_base">
    <link name='chassis'>
        <pose>0 0 .25 0 0 0</pose>
  
        <inertial>
          <mass>20.0</mass>
          <pose>-0.1 0 -0.1 0 0 0</pose>
          <inertia>
            <ixx>0.5</ixx>
            <iyy>1.0</iyy>
            <izz>0.1</izz>
          </inertia>
        </inertial>
  
        <collision name='collision'>
          <geometry>
            <box>
              <size>2 1 0.3</size>
            </box>
          </geometry>
        </collision>
  
        <visual name='visual'>
          <geometry>
            <box>
              <size>2 1 0.3</size>
            </box>
          </geometry>
        </visual>
  
        <collision name='caster_collision'>
          <pose>-0.8 0 -0.125 0 0 0</pose>
          <geometry>
            <sphere>
              <radius>.125</radius>
            </sphere>
          </geometry>
  
          <surface>
            <friction>
              <ode>
                <mu>0</mu>
                <mu2>0</mu2>
              </ode>
            </friction>
          </surface>
        </collision>
  
        <visual name='caster_visual'>
          <pose>-0.8 0 -0.125 0 0 0</pose>
          <geometry>
            <sphere>
              <radius>.125</radius>
            </sphere>
          </geometry>
        </visual>
      </link>
      <link name="left_wheel">
        <pose>0.8 0.6 0.125 0 1.5707 1.5707</pose>
        <collision name="collision">
          <geometry>
            <cylinder>
              <radius>.125</radius>
              <length>.05</length>
            </cylinder>
          </geometry>
        </collision>
        <visual name="visual">
          <geometry>
            <cylinder>
              <radius>.125</radius>
              <length>.05</length>
            </cylinder>
          </geometry>
        </visual>
      </link>
  
      <link name="right_wheel">
        <pose>0.8 -0.6 0.125 0 1.5707 1.5707</pose>
        <collision name="collision">
          <geometry>
            <cylinder>
              <radius>.125</radius>
              <length>.05</length>
            </cylinder>
          </geometry>
        </collision>
        <visual name="visual">
          <geometry>
            <cylinder>
              <radius>.125</radius>
              <length>.05</length>
            </cylinder>
          </geometry>
        </visual>
      </link>
  
      <joint type="revolute" name="left_wheel_joint">
        <pose>0 0 -0.03 0 0 0</pose>
        <child>left_wheel</child>
        <parent>chassis</parent>
        <axis>
          <use_parent_model_frame>true</use_parent_model_frame>
          <xyz>0 1 0</xyz>
        </axis>
      </joint>
  
      <joint type="revolute" name="right_wheel_joint">
        <pose>0 0 0.03 0 0 0</pose>
        <child>right_wheel</child>
        <parent>chassis</parent>
        <axis>
          <use_parent_model_frame>true</use_parent_model_frame>
          <xyz>0 1 0</xyz>
        </axis>
      </joint>

      <plugin name="differential_drive_controller" filename="libgazebo_ros_diff_drive.so">
        <updateRate>100</updateRate>
        <alwaysOn>true</alwaysOn>

        <!-- Name of left joint, defaults to `left_joint` -->
        <leftJoint>left_wheel_joint</leftJoint>

        <!-- Name of right joint, defaults to `right_joint` -->
        <rightJoint>right_wheel_joint</rightJoint>

        <!-- The distance from the center of one wheel to the other, in meters, defaults to 0.34 m -->
        <wheelSeparation>0.4</wheelSeparation>

        <!-- Diameter of the wheels, in meters, defaults to 0.15 m -->
        <wheelDiameter>0.2</wheelDiameter>

        <!-- Wheel acceleration, in rad/s^2, defaults to 0.0 rad/s^2 -->
        <wheelAcceleration>1.0</wheelAcceleration>

        <!-- Maximum torque which the wheels can produce, in Nm, defaults to 5 Nm -->
        <wheelTorque>10</wheelTorque>

        <!-- Topic to receive geometry_msgs/Twist message commands, defaults to `cmd_vel` -->
        <commandTopic>cmd_vel</commandTopic>

        <!-- Topic to publish nav_msgs/Odometry messages, defaults to `odom` -->
        <odometryTopic>odom</odometryTopic>

        <!-- Odometry frame, defaults to `odom` -->
        <odometryFrame>odom</odometryFrame>

        <!-- Robot frame to calculate odometry from, defaults to `base_footprint` -->
        <robotBaseFrame>base_link</robotBaseFrame>

        <!-- Odometry source, 0 for ENCODER, 1 for WORLD, defaults to WORLD -->
        <odometrySource>1</odometrySource>

        <!-- Set to true to publish transforms for the wheel links, defaults to false -->
        <publishWheelTF>true</publishWheelTF>

        <!-- Set to true to publish transforms for the odometry, defaults to true -->
        <publishOdom>true</publishOdom>

        <!-- Set to true to publish sensor_msgs/JointState on /joint_states for the wheel joints, defaults to false -->
        <publishWheelJointState>true</publishWheelJointState>

        <!-- Set to true to swap right and left wheels, defaults to true -->
        <legacyMode>false</legacyMode>
    </plugin>

  </model>
</sdf>